<?xml version="1.0"?>
<robot xmlns:xacro="http://www.ros.org/wiki/xacro" >    
    
    <xacro:include filename="inertial_macros.xacro"/>
    <joint name="camera_joint" type="revolute">
        <parent link="base_link"/>
        <child link="camera_link"/>
        <origin xyz="0.205 0 0.08" rpy="0 0 0"/>
        <axis xyz="0 1 0"/>
        <limit lower="0" upper="${pi/2}" velocity="100" effort="0.5"/> 
    </joint>

    <link name="camera_link">
        <visual>
            <geometry>
                <box size="0.010 0.03 0.03"/>
            </geometry>
            <material name="red"/>
        </visual>
        <collision>
            <geometry>
                <sphere radius="0.01"/>
            </geometry>
        </collision>
        <xacro:inertial_box mass="0.001" x="0.0001" y="0.0001" z="0.0001">
            <origin xyz="0 0 0" rpy="0 0 0"/>
        </xacro:inertial_box>
    </link>

    <gazebo reference="camera_link">
        <material>Gazebo/Red</material>
    </gazebo>
    
    <joint name="camera_optical_joint" type="fixed">
        <parent link="camera_link"/>
        <child link="camera_link_optical"/>
        <origin xyz="0 0 0" rpy="${-pi/2} 0 ${-pi/2}"/>
    </joint>

    <link name="camera_link_optical"></link>
    
    <gazebo>
        <plugin name="gazebo_ros_joint_state_publisher"
            filename="libgazebo_ros_joint_state_publisher.so">
            <update_rate>20</update_rate>
            <joint_name>camera_joint</joint_name>
        </plugin>
    </gazebo>
    
    <gazebo>
        <plugin name="gazebo_ros_joint_pose_trajectory"
            filename="libgazebo_ros_joint_pose_trajectory.so">
            <update_rate>2</update_rate>
        </plugin>
    </gazebo>

    <gazebo reference="camera_link">
        <material>Gazebo/Red</material>

        <sensor name="camera" type="camera">
            <pose> 0 0 0 0 0 0 </pose>
            <visualize>true</visualize>
            <update_rate>10</update_rate>
            <camera>
                <horizontal_fov>1.089</horizontal_fov>
                <image>
                    <format>R8G8B8</format>
                    <width>640</width>
                    <height>480</height>
                </image>
                <clip>
                    <near>0.05</near>
                    <far>8.0</far>
                </clip>
            </camera>
            <plugin name="camera_controller" filename="libgazebo_ros_camera.so">
                <frame_name>camera_link_optical</frame_name>
            </plugin>
            <plugin name="gazebo_ros_control" filename="libgazebo_ros_control.so">
                <robotNamespace>/</robotNamespace>
            </plugin>
            <plugin name="camera_control_plugin" filename="libcamera_control_plugin.so">
                <command_topic>/camera_control</command_topic>
                <robot_namespace>/</robot_namespace>
            </plugin>
            
        </sensor>
    </gazebo>

</robot>
